

100%|██████████| 365/365 [00:03<00:00, 94.16it/s]
100%|██████████| 365/365 [00:01<00:00, 224.18it/s]
Traceback (most recent call last):
  File "c:\Users\Frede\Documents\DTU\2024\Special Course\git\main_folder\.venv\lib\site-packages\wandb\sdk\wandb_config.py", line 162, in __getattr__
    return self.__getitem__(key)
  File "c:\Users\Frede\Documents\DTU\2024\Special Course\git\main_folder\.venv\lib\site-packages\wandb\sdk\wandb_config.py", line 130, in __getitem__
    return self._items[key]
KeyError: 'val'
The above exception was the direct cause of the following exception:
Traceback (most recent call last):
  File "C:\Users\Frede\AppData\Local\Temp\ipykernel_16204\1525155781.py", line 50, in trainModel
    if config.val == True:
  File "c:\Users\Frede\Documents\DTU\2024\Special Course\git\main_folder\.venv\lib\site-packages\wandb\sdk\wandb_config.py", line 164, in __getattr__
    raise AttributeError(
AttributeError: <class 'wandb.sdk.wandb_config.Config'> object has no attribute 'val'